Workbook

Sheet Cover
A1: Kyung Dong Navien (009450 KS): valuation model
A2: Built with src/build_model.py from DART filings. All outputs are live formulas.
A4: Summary | B4: Value
A5: Share price, 25 Sep 2026 (KRW) | B5: =Inputs!$B$6
A6: DCF value per share (KRW) | B6: =DCF!B38
A7: Upside / (downside) | B7: =DCF!B40
A8: Rating | B8: =DCF!B41
A9: WACC | B9: =DCF!B12
A10: Terminal growth | B10: =Inputs!$B$17
A11: Terminal value as % of EV | B11: =DCF!B34
A12: Check: balance sheet balances (sum of abs. differences) | B12: =SUMPRODUCT(ABS(Model!B33:G33))
A13: Check: regional revenue ties to income statement | B13: =SUMPRODUCT(ABS(Historical!B13:F13))
A14: Check: historical balance sheets balance | B14: =SUMPRODUCT(ABS(Historical!B51:F51))
A16: Legend
A17: Blue text: hardcoded input or reported figure
A18: Black text: formula
A19: Green text: link to another sheet
A20: Yellow fill: key assumption
A22: Sources
A23: DART OpenAPI (opendart.fss.or.kr): FY2025 annual report, 1H2026 half-year report, notes, filings
A24: FinanceDataReader: KOSPI listing and prices, 25 Sep 2026
A25: FRED IRLTLT01KRM156N: Korea 10-year government bond yield
A26: Damodaran Online, Jan 2026: country risk premiums, global industry betas, synthetic ratings
A27: Yahoo Finance via yfinance: peer market data (see Comps sheet for fetch date)

Sheet Inputs
A1: Inputs and assumptions
A2: Blue = hardcoded input, black = formula, green = link to another sheet, yellow = key assumption. Confirmed by the analyst on 2026-09-25.
A4: Scalar input | B4: Value | H4: Source / rationale
A5: Market data (25 Sep 2026)
A6: Share price (KRW) | B6: 60200 | H6: FinanceDataReader KOSPI listing, close 25 Sep 2026
A7: Common shares listed | B7: 14568592 | H7: FinanceDataReader KOSPI listing
A8: Treasury shares | B8: 115660 | H8: DART FY2025 annual report, treasury stock table
A9: Shares outstanding | B9: =B7-B8 | H9: Listed less treasury
A10: Discount rate
A11: Risk-free rate | B11: 0.04286 | H11: Korea 10Y government bond yield, 2026-08, FRED IRLTLT01KRM156N
A12: Equity risk premium | B12: 0.04869 | H12: Damodaran country risk premiums, Jan 2026, Korea total ERP
A13: Unlevered beta | B13: 0.8588 | H13: Damodaran global industry betas, Jan 2026, Building Materials
A14: Marginal tax rate (debt shield, relevering) | B14: 0.264 | H14: Korea statutory rate incl. local tax, Damodaran country tax rates
A15: Debt spread over risk-free | B15: 0.004 | H15: Damodaran synthetic rating, smaller firms: coverage > 12.5x = AAA. FY25 EBIT / interest paid = 15.3x
A16: Pre-tax cost of debt | B16: =B11+B15 | H16: Risk-free rate + spread
A17: Terminal growth | B17: 0.02 | H17: Bank of Korea inflation target
A18: Operating assumptions
A19: Tax rate on EBIT | B19: =AVERAGE(Historical!C30:D30) | H19: Average of tax at applicable rates / PBT, FY2024 and FY2025 (excludes deferred tax swings)
A20: Operating margin, 2H2026E | B20: =(Historical!D17-Historical!E17)/(Historical!D12-Historical!E12) | H20: Equal to 2H2025 actual margin. 1H2026 includes undisclosed US tariff refunds, so it is not extrapolated
A21: Operating margin, FY2027E onward | B21: 0.095 | H21: FY2023 to FY2025 average 9.4%, range 8.8% to 9.8%
A22: D&A / revenue | B22: 0.035 | H22: FY2024 and FY2025 both 3.5%
A23: Net working capital / revenue | B23: 0.26 | H23: FY2024 26.3%, FY2025 27.7%
A24: DPS, FY2026E onward (KRW) | B24: 750 | H24: Held at FY2025 DPS of KRW 750 (DART dividend table). No policy change assumed
A25: Commax acquisition, cash consideration | B25: 31.729097 | H25: DART 1H2026 notes, business combination (paid 2026)
A26: Rating band (+/-) | B26: 0.15 | H26: Overweight above +15%, Underweight below -15%, else Neutral
A28: Time-series input | C28: FY2026E | D28: FY2027E | E28: FY2028E | F28: FY2029E | G28: FY2030E | H28: Source / rationale
A29: Revenue growth: North America | C29: 0.07 | D29: 0.07 | E29: 0.06 | F29: 0.05 | G29: 0.04 | H29: 1H26 +7.1%. Slowing from +17.2% (FY24), +11.7% (FY25)
A30: Revenue growth: Korea (incl. Commax) | C30: 0 | D30: 0.03 | E30: 0.03 | F30: 0.03 | G30: 0.03 | H30: 1H26 flat even with Commax consolidated
A31: Revenue growth: Russia | C31: 0 | D31: 0 | E31: 0 | F31: 0 | G31: 0 | H31: FY23 to FY25 CAGR +0.1%, sanctions risk
A32: Revenue growth: China | C32: -0.05 | D32: -0.05 | E32: -0.05 | F32: -0.05 | G32: -0.05 | H32: FY23 to FY25 CAGR -12.1%
A33: Revenue growth: Other overseas | C33: 0.2 | D33: 0.15 | E33: 0.12 | F33: 0.1 | G33: 0.08 | H33: FY23 to FY25 CAGR +31.4%, small base
A34: Capex / revenue | C34: 0.07 | D34: 0.05 | E34: 0.045 | F34: 0.045 | G34: 0.045 | H34: 1H26 8.1%. Seotan expansion completed Jul 2026. Pre-expansion FY23: 5.4%

Sheet Historical
A1: Historical financials (consolidated, KRW bn)
A2: Source: DART OpenAPI, FY2025 annual report (FY2023 to FY2025) and 1H2026 half-year report. Notes items marked.
A4: KRW bn | B4: FY2023 | C4: FY2024 | D4: FY2025 | E4: 1H2025 | F4: 1H2026 | G4: Source
A5: Income statement
A6: Revenue: Korea | B6: 389.73188 | C6: 411.54974 | D6: 458.39676 | E6: 228.83141 | F6: 228.58266 | G6: DART notes, geographic disclosure
A7: Revenue: North America | B7: 660.91505 | C7: 774.93192 | D7: 865.77849 | E7: 471.57451 | F7: 504.99416 | G7: DART notes, geographic disclosure
A8: Revenue: Russia | B8: 79.872522 | C8: 78.690989 | D8: 80.044573 | E8: 28.757106 | F8: 35.326866 | G8: DART notes, geographic disclosure
A9: Revenue: China | B9: 30.857741 | C9: 30.711092 | D9: 23.935346 | E9: 6.720572 | F9: 7.872262 | G9: DART notes, geographic disclosure
A10: Revenue: Other overseas | B10: 42.935682 | C10: 57.9957 | D10: 74.084566 | E10: 21.574697 | F10: 36.74376 | G10: DART notes, geographic disclosure
A11: Total revenue | B11: =SUM(B6:B10) | C11: =SUM(C6:C10) | D11: =SUM(D6:D10) | E11: =SUM(E6:E10) | F11: =SUM(F6:F10) | G11: Formula
A12: Revenue per income statement | B12: 1204.3129 | C12: 1353.8794 | D12: 1502.2397 | E12: 757.4583 | F12: 813.51971 | G12: DART CFS
A13: Check: regions minus income statement | B13: =B11-B12 | C13: =C11-C12 | D13: =D11-D12 | E13: =E11-E12 | F13: =F11-F12 | G13: Formula
A14: Cost of sales | B14: 690.33435 | C14: 743.32016 | D14: 863.7429 | E14: 416.69589 | F14: 407.5813 | G14: DART CFS
A15: Gross profit | B15: =B12-B14 | C15: =C12-C14 | D15: =D12-D14 | E15: =E12-E14 | F15: =F12-F14 | G15: Formula
A16: SG&A | B16: 408.06798 | C16: 477.98323 | D16: 495.11993 | E16: 250.12206 | F16: 257.86694 | G16: DART CFS
A17: Operating profit | B17: 105.91054 | C17: 132.57605 | D17: 143.37689 | E17: 90.640343 | F17: 148.07147 | G17: DART CFS
A18: Depreciation and amortization | C18: 47.372658 | D18: 52.812497 | E18: 25.783551 | F18: 27.340245 | G18: DART notes, expenses by nature
A19: EBITDA | C19: =C17+C18 | D19: =D17+D18 | E19: =E17+E18 | F19: =F17+F18 | G19: Formula
A20: Profit before tax | B20: 107.29158 | C20: 152.7556 | D20: 150.64471 | E20: 82.161662 | F20: 166.18133 | G20: DART CFS
A21: Income tax expense | B21: 24.142869 | C21: 28.414675 | D21: 60.945839 | E21: 25.121183 | F21: 39.7205 | G21: DART CFS
A22: Net income | B22: 83.148711 | C22: 124.34092 | D22: 89.698872 | E22: 57.040479 | F22: 126.46083 | G22: DART CFS
A23: Net income attributable to parent | B23: 83.148711 | C23: 124.34092 | D23: 89.698872 | E23: 57.040479 | F23: 125.68805 | G23: DART CFS
A24: Tax at applicable rates (tax reconciliation) | C24: 46.41768 | D24: 44.18003 | G24: DART notes, income tax reconciliation
A25: Ratios
A26: Revenue growth | C26: =C12/B12-1 | D26: =D12/C12-1 | F26: =F12/E12-1 | G26: 1H2026 column is growth vs 1H2025
A27: Gross margin | B27: =B15/B12 | C27: =C15/C12 | D27: =D15/D12 | E27: =E15/E12 | F27: =F15/F12 | G27: Formula
A28: Operating margin | B28: =B17/B12 | C28: =C17/C12 | D28: =D17/D12 | E28: =E17/E12 | F28: =F17/F12 | G28: Formula
A29: Effective tax rate | B29: =B21/B20 | C29: =C21/C20 | D29: =D21/D20 | E29: =E21/E20 | F29: =F21/F20 | G29: Formula
A30: Tax at applicable rates / profit before tax | C30: =C24/C20 | D30: =D24/D20 | G30: Formula
A31: D&A / revenue | C31: =C18/C12 | D31: =D18/D12 | E31: =E18/E12 | F31: =F18/F12 | G31: Formula
A32: Balance sheet (period end)
A33: Cash and cash equivalents | B33: 82.771721 | C33: 100.00483 | D33: 148.68897 | F33: 150.51929 | G33: DART CFS
A34: Short-term deposits | B34: 18.84212 | C34: 24.230117 | D34: 1.6151366 | F34: 4.2857413 | G34: DART CFS
A35: Long-term deposits | B35: 9.7755905 | C35: 6.1498849 | D35: 9.6742028 | F35: 4.0064511 | G35: DART CFS
A36: Trade receivables | B36: 118.71335 | C36: 150.84662 | D36: 167.41085 | F36: 191.21462 | G36: DART CFS
A37: Inventories | B37: 300.74411 | C37: 413.81145 | D37: 419.80236 | F37: 427.04079 | G37: DART CFS
A38: Property, plant and equipment | B38: 394.37508 | C38: 468.09437 | D38: 582.23939 | F38: 680.33491 | G38: DART CFS
A39: Intangible assets and goodwill | B39: 18.515752 | C39: 32.899733 | D39: 36.510879 | F39: 41.565593 | G39: DART CFS
A40: Total assets | B40: 1060.558 | C40: 1358.8701 | D40: 1522.1671 | F40: 1671.8241 | G40: DART CFS
A41: Trade payables | B41: 152.64719 | C41: 154.74995 | D41: 147.02733 | F41: 152.13914 | G41: DART CFS
...

Sheet Model
A1: Three-statement model (KRW bn)
A2: FY2025A from Historical. FY2026E onward driven by Inputs. Simplified balance sheet: other net assets and debt held flat.
A4: KRW bn | B4: FY2025A | C4: FY2026E | D4: FY2027E | E4: FY2028E | F4: FY2029E | G4: FY2030E | H4: Note
A5: Income statement
A6: Revenue: North America | B6: =Historical!D7 | C6: =B6*(1+Inputs!C29) | D6: =C6*(1+Inputs!D29) | E6: =D6*(1+Inputs!E29) | F6: =E6*(1+Inputs!F29) | G6: =F6*(1+Inputs!G29)
A7: Revenue: Korea | B7: =Historical!D6 | C7: =B7*(1+Inputs!C30) | D7: =C7*(1+Inputs!D30) | E7: =D7*(1+Inputs!E30) | F7: =E7*(1+Inputs!F30) | G7: =F7*(1+Inputs!G30)
A8: Revenue: Russia | B8: =Historical!D8 | C8: =B8*(1+Inputs!C31) | D8: =C8*(1+Inputs!D31) | E8: =D8*(1+Inputs!E31) | F8: =E8*(1+Inputs!F31) | G8: =F8*(1+Inputs!G31)
A9: Revenue: China | B9: =Historical!D9 | C9: =B9*(1+Inputs!C32) | D9: =C9*(1+Inputs!D32) | E9: =D9*(1+Inputs!E32) | F9: =E9*(1+Inputs!F32) | G9: =F9*(1+Inputs!G32)
A10: Revenue: Other overseas | B10: =Historical!D10 | C10: =B10*(1+Inputs!C33) | D10: =C10*(1+Inputs!D33) | E10: =D10*(1+Inputs!E33) | F10: =E10*(1+Inputs!F33) | G10: =F10*(1+Inputs!G33)
A11: Total revenue | B11: =SUM(B6:B10) | C11: =SUM(C6:C10) | D11: =SUM(D6:D10) | E11: =SUM(E6:E10) | F11: =SUM(F6:F10) | G11: =SUM(G6:G10)
A12: Revenue growth | C12: =C11/B11-1 | D12: =D11/C11-1 | E12: =E11/D11-1 | F12: =F11/E11-1 | G12: =G11/F11-1
A13: Operating profit | B13: =Historical!D17 | C13: =Historical!F17+(C11-Historical!F12)*Inputs!$B$20 | D13: =D11*Inputs!$B$21 | E13: =E11*Inputs!$B$21 | F13: =F11*Inputs!$B$21 | G13: =G11*Inputs!$B$21 | H13: FY26E = 1H26 actual + 2H26 revenue x 2H margin
A14: Operating margin | B14: =B13/B11 | C14: =C13/C11 | D14: =D13/D11 | E14: =E13/E11 | F14: =F13/F11 | G14: =G13/G11
A15: D&A | B15: =Historical!D18 | C15: =C11*Inputs!$B$22 | D15: =D11*Inputs!$B$22 | E15: =E11*Inputs!$B$22 | F15: =F11*Inputs!$B$22 | G15: =G11*Inputs!$B$22
A16: EBITDA | B16: =B13+B15 | C16: =C13+C15 | D16: =D13+D15 | E16: =E13+E15 | F16: =F13+F15 | G16: =G13+G15
A17: Net interest expense | B17: =Historical!D17-Historical!D20 | C17: =B31*Inputs!$B$16-B26*Inputs!$B$11 | D17: =C31*Inputs!$B$16-C26*Inputs!$B$11 | E17: =D31*Inputs!$B$16-D26*Inputs!$B$11 | F17: =E31*Inputs!$B$16-E26*Inputs!$B$11 | G17: =F31*Inputs!$B$16-F26*Inputs!$B$11 | H17: Opening debt x cost of debt - opening cash x risk-free. FY25A: OP - PBT (incl. other items)
A18: Profit before tax | B18: =Historical!D20 | C18: =C13-C17 | D18: =D13-D17 | E18: =E13-E17 | F18: =F13-F17 | G18: =G13-G17
A19: Income tax | B19: =Historical!D21 | C19: =C18*Inputs!$B$19 | D19: =D18*Inputs!$B$19 | E19: =E18*Inputs!$B$19 | F19: =F18*Inputs!$B$19 | G19: =G18*Inputs!$B$19
A20: Net income | B20: =Historical!D22 | C20: =C18-C19 | D20: =D18-D19 | E20: =E18-E19 | F20: =F18-F19 | G20: =G18-G19 | H20: Minority share of Commax ignored (NCI 1% of equity)
A21: EPS (KRW) | B21: =B20*1000000000/Inputs!$B$9 | C21: =C20*1000000000/Inputs!$B$9 | D21: =D20*1000000000/Inputs!$B$9 | E21: =E20*1000000000/Inputs!$B$9 | F21: =F20*1000000000/Inputs!$B$9 | G21: =G20*1000000000/Inputs!$B$9
A22: DPS (KRW) | B22: =Inputs!$B$24 | C22: =Inputs!$B$24 | D22: =Inputs!$B$24 | E22: =Inputs!$B$24 | F22: =Inputs!$B$24 | G22: =Inputs!$B$24
A23: Dividends | C23: =C22*Inputs!$B$9/1000000000 | D23: =D22*Inputs!$B$9/1000000000 | E23: =E22*Inputs!$B$9/1000000000 | F23: =F22*Inputs!$B$9/1000000000 | G23: =G22*Inputs!$B$9/1000000000
A24: ROE (on opening equity) | C24: =C20/B32 | D24: =D20/C32 | E24: =E20/D32 | F24: =F20/E32 | G24: =G20/F32
A25: Balance sheet (year end, simplified)
A26: Cash and deposits | B26: =Historical!D52 | C26: =B26+C43 | D26: =C26+D43 | E26: =D26+E43 | F26: =E26+F43 | G26: =F26+G43 | H26: Plug from cash flow
A27: Net working capital | B27: =Historical!D53 | C27: =C11*Inputs!$B$23 | D27: =D11*Inputs!$B$23 | E27: =E11*Inputs!$B$23 | F27: =F11*Inputs!$B$23 | G27: =G11*Inputs!$B$23
A28: Net fixed assets | B28: =Historical!D57 | C28: =B28+C39-C15 | D28: =C28+D39-D15 | E28: =D28+E39-E15 | F28: =E28+F39-F15 | G28: =F28+G39-G15
A29: Other net assets | B29: =B31+B32-B26-B27-B28 | C29: =B29+C40 | D29: =C29+D40 | E29: =D29+E40 | F29: =E29+F40 | G29: =F29+G40 | H29: FY25A balancing item from reported totals. Grows only by acquisitions
A30: Total net assets | B30: =SUM(B26:B29) | C30: =SUM(C26:C29) | D30: =SUM(D26:D29) | E30: =SUM(E26:E29) | F30: =SUM(F26:F29) | G30: =SUM(G26:G29)
A31: Gross debt | B31: =Historical!D55 | C31: =B31+C42 | D31: =C31+D42 | E31: =D31+E42 | F31: =E31+F42 | G31: =F31+G42
A32: Total equity | B32: =Historical!D50 | C32: =B32+C20-C23 | D32: =C32+D20-D23 | E32: =D32+E20-E23 | F32: =E32+F20-F23 | G32: =F32+G20-G23
A33: Check: net assets - debt - equity (must be 0) | B33: =B30-B31-B32 | C33: =C30-C31-C32 | D33: =D30-D31-D32 | E33: =E30-E31-E32 | F33: =F30-F31-F32 | G33: =G30-G31-G32
A34: Cash flow statement
A35: Net income | C35: =C20 | D35: =D20 | E35: =E20 | F35: =F20 | G35: =G20
A36: Add: D&A | C36: =C15 | D36: =D15 | E36: =E15 | F36: =F15 | G36: =G15
A37: Less: increase in net working capital | C37: =-(C27-B27) | D37: =-(D27-C27) | E37: =-(E27-D27) | F37: =-(F27-E27) | G37: =-(G27-F27)
A38: Cash flow from operations | C38: =C35+C36+C37 | D38: =D35+D36+D37 | E38: =E35+E36+E37 | F38: =F35+F36+F37 | G38: =G35+G36+G37
A39: Capex | B39: =Historical!D62 | C39: =C11*Inputs!C34 | D39: =D11*Inputs!D34 | E39: =E11*Inputs!E34 | F39: =F11*Inputs!F34 | G39: =G11*Inputs!G34
A40: Acquisitions | C40: =Inputs!$B$25 | D40: =0 | E40: =0 | F40: =0 | G40: =0
A41: Dividends paid | C41: =C23 | D41: =D23 | E41: =E23 | F41: =F23 | G41: =G23
...

Sheet DCF
A1: DCF valuation (FCFF, KRW bn)
A2: Valuation date 30 Jun 2026 (latest balance sheet). Cash flows from 2H2026. Mid-period discounting.
A4: Cost of capital | B4: Value | G4: Note
A5: Market cap | B5: =Inputs!$B$6*Inputs!$B$9/1000000000 | G5: Price x shares outstanding
A6: Gross debt, 30 Jun 2026 | B6: =Historical!F55
A7: Debt / equity | B7: =B6/B5
A8: Levered beta | B8: =Inputs!$B$13*(1+(1-Inputs!$B$14)*B7) | G8: Unlevered beta x (1 + (1 - t) x D/E)
A9: Cost of equity | B9: =Inputs!$B$11+B8*Inputs!$B$12 | G9: CAPM
A10: After-tax cost of debt | B10: =Inputs!$B$16*(1-Inputs!$B$14)
A11: Equity weight | B11: =B5/(B5+B6)
A12: WACC | B12: =B11*B9+(1-B11)*B10
A14: Free cash flow to firm | B14: 2H2026E | C14: FY2027E | D14: FY2028E | E14: FY2029E | F14: FY2030E | G14: Note
A15: Revenue | B15: =Model!C11-Historical!F12 | C15: =Model!D11 | D15: =Model!E11 | E15: =Model!F11 | F15: =Model!G11 | G15: 2H26 = FY26E - 1H26 actual
A16: EBIT (operating profit) | B16: =Model!C13-Historical!F17 | C16: =Model!D13 | D16: =Model!E13 | E16: =Model!F13 | F16: =Model!G13
A17: Less: tax on EBIT | B17: =-B16*Inputs!$B$19 | C17: =-C16*Inputs!$B$19 | D17: =-D16*Inputs!$B$19 | E17: =-E16*Inputs!$B$19 | F17: =-F16*Inputs!$B$19
A18: NOPAT | B18: =B16+B17 | C18: =C16+C17 | D18: =D16+D17 | E18: =E16+E17 | F18: =F16+F17
A19: Add: D&A | B19: =Model!C15-Historical!F18 | C19: =Model!D15 | D19: =Model!E15 | E19: =Model!F15 | F19: =Model!G15
A20: Less: capex | B20: =-(Model!C39-Historical!F62) | C20: =-Model!D39 | D20: =-Model!E39 | E20: =-Model!F39 | F20: =-Model!G39
A21: Less: increase in net working capital | B21: =-(Model!C27-Historical!F53) | C21: =-(Model!D27-Model!C27) | D21: =-(Model!E27-Model!D27) | E21: =-(Model!F27-Model!E27) | F21: =-(Model!G27-Model!F27) | G21: 2H26 vs 30 Jun 2026 actual NWC
A22: Free cash flow to firm | B22: =B18+B19+B20+B21 | C22: =C18+C19+C20+C21 | D22: =D18+D19+D20+D21 | E22: =E18+E19+E20+E21 | F22: =F18+F19+F20+F21
A23: Discount period, mid-point (years from 30 Jun 2026) | B23: 0.25 | C23: 1 | D23: 2 | E23: 3 | F23: 4 | G23: 2H26 mid-point 0.25y, then full years centred at 1.0, 2.0, 3.0, 4.0
A24: Discount factor | B24: =1/(1+$B$12)^B23 | C24: =1/(1+$B$12)^C23 | D24: =1/(1+$B$12)^D23 | E24: =1/(1+$B$12)^E23 | F24: =1/(1+$B$12)^F23
A25: PV of FCFF | B25: =B22*B24 | C25: =C22*C24 | D25: =D22*D24 | E25: =E22*E24 | F25: =F22*F24
A26: Memo: revenue at long-term margin (for sensitivity) | B26: =0 | C26: =C15 | D26: =D15 | E26: =E15 | F26: =F15
A28: Valuation | B28: Value | G28: Note
A29: Sum of PV of FCFF | B29: =SUM(B25:F25)
A30: Terminal value at end FY2030 | B30: =F22*(1+Inputs!$B$17)/(B12-Inputs!$B$17) | G30: FCFF FY2030 x (1 + g) / (WACC - g)
A31: Terminal discount period (years) | B31: 4.5 | G31: End of FY2030 = 4.5 years after 30 Jun 2026
A32: PV of terminal value | B32: =B30/(1+B12)^B31
A33: Enterprise value | B33: =B29+B32
A34: Terminal value as % of EV | B34: =B32/B33
A35: Less: net debt, 30 Jun 2026 | B35: =Historical!F56
A36: Less: non-controlling interests, 30 Jun 2026 | B36: =Historical!F49
A37: Equity value | B37: =B33-B35-B36
A38: Equity value per share (KRW) | B38: =B37*1000000000/Inputs!$B$9
A39: Current price (KRW) | B39: =Inputs!$B$6
A40: Upside / (downside) | B40: =B38/B39-1
A41: Rating | B41: =IF(B40>Inputs!$B$26,"Overweight",IF(B40<-Inputs!$B$26,"Underweight","Neutral"))
A42: Implied EV / EBITDA FY2026E | B42: =B33/Model!C16
A43: Implied EV / EBITDA FY2027E | B43: =B33/Model!D16
...

Sheet Comps
A1: Trading comparables
A2: Peer data: Yahoo Finance via yfinance, fetched 2026-09-25. Local currency, millions. Multiples are computed here from raw values.
A4: Company | B4: Ticker | C4: Currency | D4: Market cap (m) | E4: EV (m) | F4: EBITDA TTM (m) | G4: Net income TTM (m) | H4: EV/EBITDA | I4: P/E TTM | J4: P/E fwd | K4: P/B | L4: ROE | M4: Op. margin
A5: A. O. Smith | B5: AOS | C5: USD | D5: 7971 | E5: 8337.8 | F5: 783.7 | G5: 500.3 | H5: =E5/F5 | I5: =D5/G5 | J5: 14.3528 | K5: 4.3278 | L5: 0.2713 | M5: 0.1893
A6: Rinnai | B6: 5947.T | C6: JPY | D6: 476340.2 | E6: 359255.1 | F6: 64900.8 | G6: 36282 | H6: =E6/F6 | I6: =D6/G6 | J6: 15.1163 | K6: 1.0878 | L6: 0.0918 | M6: 0.0807
A7: Noritz | B7: 5943.T | C7: JPY | D7: 101138.9 | E7: 84300.6 | F7: 13466 | G7: 7150 | H7: =E7/F7 | I7: =D7/G7 | J7: 31.9735 | K7: 0.71 | L7: 0.0512 | M7: 0.0032
A8: Ariston Holding | B8: ARIS.MI | C8: EUR | D8: 1470 | E8: 2094.7 | F8: 249.7 | G8: 109.2 | H8: =E8/F8 | I8: =D8/G8 | J8: 9.8534 | K8: 0.8959 | L8: 0.0735 | M8: 0.0461
A9: Lennox International | B9: LII | C9: USD | D9: 12917.7 | E9: 14683.3 | F9: 1170.8 | G9: 788.5 | H9: =E9/F9 | I9: =D9/G9 | J9: 14.3 | K9: 9.9576 | L9: 0.7176 | M9: 0.2286
A10: Coway | B10: 021240.KS | C10: KRW | D10: 6998865.2 | E10: 9524181.2 | F10: 1330515.5 | G10: 683539.9 | H10: =E10/F10 | I10: =D10/G10 | J10: 8.9324 | K10: n/a | L10: 0.1931 | M10: 0.1756
A11: Peer median | H11: =MEDIAN(H5:H10) | I11: =MEDIAN(I5:I10) | J11: =MEDIAN(J5:J10) | K11: =MEDIAN(K5:K10) | L11: =MEDIAN(L5:L10) | M11: =MEDIAN(M5:M10)
A13: Kyung Dong Navien (KRW bn)
A14: Market cap | B14: =DCF!B5
A15: Enterprise value | B15: =B14+Historical!F56+Historical!F49 | C15: Market cap + net debt + NCI, 30 Jun 2026
A16: EBITDA, LTM to 1H2026 | B16: =Historical!D17+Historical!D18-(Historical!E17+Historical!E18)+Historical!F17+Historical!F18 | C16: FY2025 - 1H2025 + 1H2026. Includes undisclosed US tariff refunds in 1H2026
A17: Net income to parent, LTM | B17: =Historical!D23-Historical!E23+Historical!F23
A18: EV / EBITDA, LTM | B18: =B15/B16
A19: P/E, LTM | B19: =B14/B17
A20: P/E, FY2027E (model) | B20: =B14/Model!D20 | C20: FY2027E is the first year with no tariff refund assumed
A21: P/B, 30 Jun 2026 | B21: =B14/Historical!F48
A23: Implied value per share at peer median (KRW)
A24: At median EV / EBITDA (LTM) | B24: =(H11*B16-Historical!F56-Historical!F49)*1000000000/Inputs!$B$9 | C24: Cross-check only, not blended into the target
A25: At median P/E (LTM) | B25: =I11*B17*1000000000/Inputs!$B$9
A26: At median forward P/E on FY2027E net income | B26: =J11*Model!D20*1000000000/Inputs!$B$9
A27: DCF value per share | B27: =DCF!B38
